Workbook

Sheet Journal
A1: Himalayan Traders Pvt. Ltd.
A2: Journal — Financial Year 2024-25
A3: Currency: NPR | Blue = user input | Black = formula | Green = cross-sheet link
A5: S.No | B5: Date | C5: Narration | D5: Account | E5: Debit | F5: Credit
A6: 1 | B6: 2024-04-01 | C6: Started business with cash as capital | D6: Cash in Hand | E6: 200000
D7: Capital Account | F7: 200000
A8: 2 | B8: 2024-04-05 | C8: Opened bank account and deposited cash | D8: Bank A/c | E8: 80000
D9: Cash in Hand | F9: 80000
A10: 3 | B10: 2024-04-10 | C10: Cash purchase of goods | D10: Purchases | E10: 30000
D11: Cash in Hand | F11: 30000
A12: 4 | B12: 2024-04-15 | C12: Credit purchase of goods from Supplier A | D12: Purchases | E12: 25000
D13: Creditors - Supplier A | F13: 25000
A14: 5 | B14: 2024-04-20 | C14: Credit sale of goods to Customer X | D14: Debtors - Customer X | E14: 40000
D15: Sales | F15: 40000
A16: 6 | B16: 2024-05-03 | C16: Cash sale of goods | D16: Cash in Hand | E16: 15000
D17: Sales | F17: 15000
A18: 7 | B18: 2024-05-10 | C18: Paid shop rent | D18: Rent Paid | E18: 5000
D19: Cash in Hand | F19: 5000
A20: 8 | B20: 2024-05-15 | C20: Paid salary to staff | D20: Salary | E20: 8000
D21: Cash in Hand | F21: 8000
A22: 9 | B22: 2024-06-01 | C22: Purchased furniture by cheque | D22: Furniture & Fixtures | E22: 12000
D23: Bank A/c | F23: 12000
A24: 10 | B24: 2024-06-15 | C24: Credit sale to Customer Y | D24: Debtors - Customer Y | E24: 30000
D25: Sales | F25: 30000
A26: 11 | B26: 2024-07-05 | C26: Received from Customer X, allowed discount | D26: Bank A/c | E26: 38000
D27: Discount Allowed | E27: 2000
D28: Debtors - Customer X | F28: 40000
A29: 12 | B29: 2024-07-20 | C29: Paid to Supplier A, received discount | D29: Creditors - Supplier A | E29: 25000
D30: Bank A/c | F30: 24500
D31: Discount Received | F31: 500
A32: 13 | B32: 2024-08-10 | C32: Paid insurance premium by cheque | D32: Insurance | E32: 2000
D33: Bank A/c | F33: 2000
A34: 14 | B34: 2024-09-01 | C34: Cash purchase of goods | D34: Purchases | E34: 20000
D35: Cash in Hand | F35: 20000
A36: 15 | B36: 2024-10-15 | C36: Credit sale to Customer Z | D36: Debtors - Customer Z | E36: 35000
D37: Sales | F37: 35000
A38: 16 | B38: 2024-11-01 | C38: Paid advertisement expenses by cheque | D38: Advertisement | E38: 3000
D39: Bank A/c | F39: 3000
A40: 17 | B40: 2024-12-15 | C40: Owner withdrew cash for personal use | D40: Drawings | E40: 5000
D41: Cash in Hand | F41: 5000
...

Sheet Trial Balance
A1: Himalayan Traders Pvt. Ltd.
A2: Trial Balance
A3: as at the close of the financial year (pre-adjustment ledger balances)
A5: Account | B5: Classification | C5: Debit (Rs) | D5: Credit (Rs)
A6: Cash in Hand | B6: BS — Asset | C6: =IF((SUMIF(Journal!$D$6:$D$47,A6,Journal!$E$6:$E$47)-SUMIF(Journal!$D$6:$D$47,A6,Journal!$F$6:$F$47))>=0,(SUMIF(Journal!$D$6:$D$47,A6,Journal!$E$6:$E$47)-SUMIF(Journal!$D$6:$D$47,A6,Journal!$F$6:$F$47)),0) -> 87500 | D6: =IF((SUMIF(Journal!$D$6:$D$47,A6,Journal!$E$6:$E$47)-SUMIF(Journal!$D$6:$D$47,A6,Journal!$F$6:$F$47))<0,-(SUMIF(Journal!$D$6:$D$47,A6,Journal!$E$6:$E$47)-SUMIF(Journal!$D$6:$D$47,A6,Journal!$F$6:$F$47)),0) -> 0
A7: Capital Account | B7: BS — Capital | C7: =IF((SUMIF(Journal!$D$6:$D$47,A7,Journal!$E$6:$E$47)-SUMIF(Journal!$D$6:$D$47,A7,Journal!$F$6:$F$47))>=0,(SUMIF(Journal!$D$6:$D$47,A7,Journal!$E$6:$E$47)-SUMIF(Journal!$D$6:$D$47,A7,Journal!$F$6:$F$47)),0) -> 0 | D7: =IF((SUMIF(Journal!$D$6:$D$47,A7,Journal!$E$6:$E$47)-SUMIF(Journal!$D$6:$D$47,A7,Journal!$F$6:$F$47))<0,-(SUMIF(Journal!$D$6:$D$47,A7,Journal!$E$6:$E$47)-SUMIF(Journal!$D$6:$D$47,A7,Journal!$F$6:$F$47)),0) -> 200000
A8: Bank A/c | B8: BS — Asset | C8: =IF((SUMIF(Journal!$D$6:$D$47,A8,Journal!$E$6:$E$47)-SUMIF(Journal!$D$6:$D$47,A8,Journal!$F$6:$F$47))>=0,(SUMIF(Journal!$D$6:$D$47,A8,Journal!$E$6:$E$47)-SUMIF(Journal!$D$6:$D$47,A8,Journal!$F$6:$F$47)),0) -> 76500 | D8: =IF((SUMIF(Journal!$D$6:$D$47,A8,Journal!$E$6:$E$47)-SUMIF(Journal!$D$6:$D$47,A8,Journal!$F$6:$F$47))<0,-(SUMIF(Journal!$D$6:$D$47,A8,Journal!$E$6:$E$47)-SUMIF(Journal!$D$6:$D$47,A8,Journal!$F$6:$F$47)),0) -> 0
A9: Purchases | B9: Trading (Dr) | C9: =IF((SUMIF(Journal!$D$6:$D$47,A9,Journal!$E$6:$E$47)-SUMIF(Journal!$D$6:$D$47,A9,Journal!$F$6:$F$47))>=0,(SUMIF(Journal!$D$6:$D$47,A9,Journal!$E$6:$E$47)-SUMIF(Journal!$D$6:$D$47,A9,Journal!$F$6:$F$47)),0) -> 93000 | D9: =IF((SUMIF(Journal!$D$6:$D$47,A9,Journal!$E$6:$E$47)-SUMIF(Journal!$D$6:$D$47,A9,Journal!$F$6:$F$47))<0,-(SUMIF(Journal!$D$6:$D$47,A9,Journal!$E$6:$E$47)-SUMIF(Journal!$D$6:$D$47,A9,Journal!$F$6:$F$47)),0) -> 0
A10: Creditors - Supplier A | B10: BS — Liability | C10: =IF((SUMIF(Journal!$D$6:$D$47,A10,Journal!$E$6:$E$47)-SUMIF(Journal!$D$6:$D$47,A10,Journal!$F$6:$F$47))>=0,(SUMIF(Journal!$D$6:$D$47,A10,Journal!$E$6:$E$47)-SUMIF(Journal!$D$6:$D$47,A10,Journal!$F$6:$F$47)),0) -> 0 | D10: =IF((SUMIF(Journal!$D$6:$D$47,A10,Journal!$E$6:$E$47)-SUMIF(Journal!$D$6:$D$47,A10,Journal!$F$6:$F$47))<0,-(SUMIF(Journal!$D$6:$D$47,A10,Journal!$E$6:$E$47)-SUMIF(Journal!$D$6:$D$47,A10,Journal!$F$6:$F$47)),0) -> 0
A11: Debtors - Customer X | B11: BS — Asset | C11: =IF((SUMIF(Journal!$D$6:$D$47,A11,Journal!$E$6:$E$47)-SUMIF(Journal!$D$6:$D$47,A11,Journal!$F$6:$F$47))>=0,(SUMIF(Journal!$D$6:$D$47,A11,Journal!$E$6:$E$47)-SUMIF(Journal!$D$6:$D$47,A11,Journal!$F$6:$F$47)),0) -> 0 | D11: =IF((SUMIF(Journal!$D$6:$D$47,A11,Journal!$E$6:$E$47)-SUMIF(Journal!$D$6:$D$47,A11,Journal!$F$6:$F$47))<0,-(SUMIF(Journal!$D$6:$D$47,A11,Journal!$E$6:$E$47)-SUMIF(Journal!$D$6:$D$47,A11,Journal!$F$6:$F$47)),0) -> 0
A12: Sales | B12: Trading (Cr) | C12: =IF((SUMIF(Journal!$D$6:$D$47,A12,Journal!$E$6:$E$47)-SUMIF(Journal!$D$6:$D$47,A12,Journal!$F$6:$F$47))>=0,(SUMIF(Journal!$D$6:$D$47,A12,Journal!$E$6:$E$47)-SUMIF(Journal!$D$6:$D$47,A12,Journal!$F$6:$F$47)),0) -> 0 | D12: =IF((SUMIF(Journal!$D$6:$D$47,A12,Journal!$E$6:$E$47)-SUMIF(Journal!$D$6:$D$47,A12,Journal!$F$6:$F$47))<0,-(SUMIF(Journal!$D$6:$D$47,A12,Journal!$E$6:$E$47)-SUMIF(Journal!$D$6:$D$47,A12,Journal!$F$6:$F$47)),0) -> 142000
A13: Rent Paid | B13: P&L (Dr) | C13: =IF((SUMIF(Journal!$D$6:$D$47,A13,Journal!$E$6:$E$47)-SUMIF(Journal!$D$6:$D$47,A13,Journal!$F$6:$F$47))>=0,(SUMIF(Journal!$D$6:$D$47,A13,Journal!$E$6:$E$47)-SUMIF(Journal!$D$6:$D$47,A13,Journal!$F$6:$F$47)),0) -> 5000 | D13: =IF((SUMIF(Journal!$D$6:$D$47,A13,Journal!$E$6:$E$47)-SUMIF(Journal!$D$6:$D$47,A13,Journal!$F$6:$F$47))<0,-(SUMIF(Journal!$D$6:$D$47,A13,Journal!$E$6:$E$47)-SUMIF(Journal!$D$6:$D$47,A13,Journal!$F$6:$F$47)),0) -> 0
A14: Salary | B14: P&L (Dr) | C14: =IF((SUMIF(Journal!$D$6:$D$47,A14,Journal!$E$6:$E$47)-SUMIF(Journal!$D$6:$D$47,A14,Journal!$F$6:$F$47))>=0,(SUMIF(Journal!$D$6:$D$47,A14,Journal!$E$6:$E$47)-SUMIF(Journal!$D$6:$D$47,A14,Journal!$F$6:$F$47)),0) -> 8000 | D14: =IF((SUMIF(Journal!$D$6:$D$47,A14,Journal!$E$6:$E$47)-SUMIF(Journal!$D$6:$D$47,A14,Journal!$F$6:$F$47))<0,-(SUMIF(Journal!$D$6:$D$47,A14,Journal!$E$6:$E$47)-SUMIF(Journal!$D$6:$D$47,A14,Journal!$F$6:$F$47)),0) -> 0
A15: Furniture & Fixtures | B15: BS — Asset | C15: =IF((SUMIF(Journal!$D$6:$D$47,A15,Journal!$E$6:$E$47)-SUMIF(Journal!$D$6:$D$47,A15,Journal!$F$6:$F$47))>=0,(SUMIF(Journal!$D$6:$D$47,A15,Journal!$E$6:$E$47)-SUMIF(Journal!$D$6:$D$47,A15,Journal!$F$6:$F$47)),0) -> 12000 | D15: =IF((SUMIF(Journal!$D$6:$D$47,A15,Journal!$E$6:$E$47)-SUMIF(Journal!$D$6:$D$47,A15,Journal!$F$6:$F$47))<0,-(SUMIF(Journal!$D$6:$D$47,A15,Journal!$E$6:$E$47)-SUMIF(Journal!$D$6:$D$47,A15,Journal!$F$6:$F$47)),0) -> 0
A16: Debtors - Customer Y | B16: BS — Asset | C16: =IF((SUMIF(Journal!$D$6:$D$47,A16,Journal!$E$6:$E$47)-SUMIF(Journal!$D$6:$D$47,A16,Journal!$F$6:$F$47))>=0,(SUMIF(Journal!$D$6:$D$47,A16,Journal!$E$6:$E$47)-SUMIF(Journal!$D$6:$D$47,A16,Journal!$F$6:$F$47)),0) -> 30000 | D16: =IF((SUMIF(Journal!$D$6:$D$47,A16,Journal!$E$6:$E$47)-SUMIF(Journal!$D$6:$D$47,A16,Journal!$F$6:$F$47))<0,-(SUMIF(Journal!$D$6:$D$47,A16,Journal!$E$6:$E$47)-SUMIF(Journal!$D$6:$D$47,A16,Journal!$F$6:$F$47)),0) -> 0
A17: Discount Allowed | B17: P&L (Dr) | C17: =IF((SUMIF(Journal!$D$6:$D$47,A17,Journal!$E$6:$E$47)-SUMIF(Journal!$D$6:$D$47,A17,Journal!$F$6:$F$47))>=0,(SUMIF(Journal!$D$6:$D$47,A17,Journal!$E$6:$E$47)-SUMIF(Journal!$D$6:$D$47,A17,Journal!$F$6:$F$47)),0) -> 2000 | D17: =IF((SUMIF(Journal!$D$6:$D$47,A17,Journal!$E$6:$E$47)-SUMIF(Journal!$D$6:$D$47,A17,Journal!$F$6:$F$47))<0,-(SUMIF(Journal!$D$6:$D$47,A17,Journal!$E$6:$E$47)-SUMIF(Journal!$D$6:$D$47,A17,Journal!$F$6:$F$47)),0) -> 0
... A24: Creditors - Supplier B | B24: BS — Liability | C24: =IF((SUMIF(Journal!$D$6:$D$47,A24,Journal!$E$6:$E$47)-SUMIF(Journal!$D$6:$D$47,A24,Journal!$F$6:$F$47))>=0,(SUMIF(Journal!$D$6:$D$47,A24,Journal!$E$6:$E$47)-SUMIF(Journal!$D$6:$D$47,A24,Journal!$F$6:$F$47)),0) -> 0 | D24: =IF((SUMIF(Journal!$D$6:$D$47,A24,Journal!$E$6:$E$47)-SUMIF(Journal!$D$6:$D$47,A24,Journal!$F$6:$F$47))<0,-(SUMIF(Journal!$D$6:$D$47,A24,Journal!$E$6:$E$47)-SUMIF(Journal!$D$6:$D$47,A24,Journal!$F$6:$F$47)),0) -> 18000
A25: TOTAL | C25: =SUM(C6:C24) -> 360500 | D25: =SUM(D6:D24) -> 360500
A26: Dr total − Cr total (should be 0) | C26: =C25-D25 -> 0

Sheet Adjustments
A1: Himalayan Traders Pvt. Ltd.
A2: Adjustments
A3: Period-end items not yet in the Journal. Blue = assumption; Green = formula linked to Trial Balance.
A5: # | B5: Adjustment | C5: Account / Base | D5: Amount | E5: Narration
A6: 1 | B6: Closing stock valued at cost at year end | C6: Closing Stock | D6: 40000 | E6: Closing stock valued at cost at year end
A7: 2 | B7: Depreciation on Furniture & Fixtures @ 10% p.a. | C7: =('Trial Balance'!C15+'Trial Balance'!D15) -> 12000 | D7: =('Trial Balance'!C15+'Trial Balance'!D15)*0.1 -> 1200 | E7: Depreciation on furniture @ 10% p.a.
A8: 3 | B8: Salary outstanding at year end | C8: Salary | D8: 2000 | E8: Salary outstanding at year end
A9: 4 | B9: Insurance prepaid at year end | C9: Insurance | D9: 500 | E9: Insurance prepaid at year end

Sheet Trading Account
A1: Himalayan Traders Pvt. Ltd.
A2: Trading Account
A3: for the year ended 31 March 2025
A5: Particulars | B5: Amount (Dr) | C5: Particulars | D5: Amount (Cr)
A6: To Purchases | B6: ='Trial Balance'!C9 -> 93000 | C6: By Sales | D6: ='Trial Balance'!D12 -> 142000
C7: By Closing Stock (Adjusted) | D7: =Adjustments!D6 -> 40000
A8: To Gross Profit c/d | B8: =IF(SUM(D6:D7)>SUM(B6:B7),SUM(D6:D7)-SUM(B6:B7),0) -> 89000 | C8: By Gross Loss c/d | D8: =IF(SUM(B6:B7)>SUM(D6:D7),SUM(B6:B7)-SUM(D6:D7),0) -> 0
A9: TOTAL | B9: =SUM(B6:B8) -> 182000 | C9: TOTAL | D9: =SUM(D6:D8) -> 182000

Sheet Profit & Loss Account
A1: Himalayan Traders Pvt. Ltd.
A2: Profit & Loss Account
A3: for the year ended 31 March 2025
A5: Particulars | B5: Amount (Dr) | C5: Particulars | D5: Amount (Cr)
C6: By Gross Profit b/d | D6: ='Trading Account'!D8+'Trading Account'!B8 -> 89000
A7: To Rent Paid | B7: ='Trial Balance'!C13 -> 5000 | C7: By Discount Received | D7: ='Trial Balance'!D18 -> 500
A8: To Salary | B8: ='Trial Balance'!C14 -> 8000 | C8: By Prepaid Insurance | D8: =Adjustments!D9 -> 500
A9: To Discount Allowed | B9: ='Trial Balance'!C17 -> 2000
A10: To Insurance | B10: ='Trial Balance'!C19 -> 2000
A11: To Advertisement | B11: ='Trial Balance'!C21 -> 3000
A12: To Electricity | B12: ='Trial Balance'!C23 -> 1500
A13: To Depreciation on Furniture & Fixtures | B13: =Adjustments!D7 -> 1200
A14: To Outstanding Salary | B14: =Adjustments!D8 -> 2000
A15: To Net Profit (transferred to Capital) | B15: =IF(SUM(D6:D14)>SUM(B6:B14),SUM(D6:D14)-SUM(B6:B14),0) -> 65300 | C15: By Net Loss (transferred to Capital) | D15: =IF(SUM(B6:B14)>SUM(D6:D14),SUM(B6:B14)-SUM(D6:D14),0) -> 0
A16: TOTAL | B16: =SUM(B6:B15) -> 90000 | C16: TOTAL | D16: =SUM(D6:D15) -> 90000

Sheet Balance Sheet
A1: Himalayan Traders Pvt. Ltd.
A2: Balance Sheet
A3: as at 31 March 2025
A5: Capital & Liabilities | B5: Amount | C5: Assets | D5: Amount
A6: Capital Account (opening) | B6: ='Trial Balance'!D7-'Trial Balance'!C7 -> 200000 | C6: Furniture & Fixtures | D6: ='Trial Balance'!C15-'Trial Balance'!D15 -> 12000
A7: Add: Net Profit (from P&L A/c) | B7: ='Profit & Loss Account'!B15 -> 65300 | C7: Less: Depreciation | D7: =Adjustments!D7 -> 1200
A8: Less: Net Loss (from P&L A/c) | B8: ='Profit & Loss Account'!D15 -> 0 | C8: Furniture & Fixtures (after depreciation) | D8: =D6-D7 -> 10800
A9: Less: Drawings | B9: ='Trial Balance'!C22-'Trial Balance'!D22 -> 5000 | C9: Closing Stock (Adjusted) | D9: =Adjustments!D6 -> 40000
A10: Capital (closing balance) | B10: =B6+B7-B8-B9 -> 260300 | C10: Cash in Hand | D10: ='Trial Balance'!C6-'Trial Balance'!D6 -> 87500
A11: Creditors - Supplier A | B11: ='Trial Balance'!D10-'Trial Balance'!C10 -> 0 | C11: Bank A/c | D11: ='Trial Balance'!C8-'Trial Balance'!D8 -> 76500
A12: Creditors - Supplier B | B12: ='Trial Balance'!D24-'Trial Balance'!C24 -> 18000 | C12: Debtors - Customer X | D12: ='Trial Balance'!C11-'Trial Balance'!D11 -> 0
A13: Outstanding Salary | B13: =Adjustments!D8 -> 2000 | C13: Debtors - Customer Y | D13: ='Trial Balance'!C16-'Trial Balance'!D16 -> 30000
C14: Debtors - Customer Z | D14: ='Trial Balance'!C20-'Trial Balance'!D20 -> 35000
C15: Prepaid Insurance | D15: =Adjustments!D9 -> 500
A16: TOTAL | B16: =B10+B11+B12+B13 -> 280300 | C16: TOTAL | D16: =D8+D9+D10+D11+D12+D13+D14+D15 -> 280300
A17: Balance check (Liabilities − Assets, should be 0) | B17: =B16-D16 -> 0

Sheet Notes - Formulas Used
A1: Notes — Formulas Used & Assumptions
A2: Every figure in this workbook is a live Excel formula. Blue = user input / assumption. Green = cross-sheet reference. Black = in-sheet formula.
A4: # | B4: Equation / Rule | C4: Where used
A5: 1 | B5: Double-entry rule: every journal entry has ΣDebit = ΣCredit | C5: Journal sheet — TOTAL row + Dr−Cr check
A6: 2 | B6: Trial Balance: Account Dr balance = MAX(SUMIF(Journal.Account, name, Journal.Debit) − SUMIF(...,Journal.Credit), 0); Cr balance = MAX(negative of that, 0) | C6: Trial Balance — columns C (Dr) and D (Cr)
A7: 3 | B7: Trial Balance must balance: ΣDr = ΣCr (Dr−Cr check row = 0) | C7: Trial Balance — TOTAL + check rows
A8: 4 | B8: Closing Stock is a period-end input, posted only via Adjustments sheet | C8: Adjustments → Trading A/c (Cr) + Balance Sheet (Asset)
A9: 5 | B9: Depreciation = (Trial Balance asset balance) × rate% | C9: Adjustments sheet → Balance Sheet (deducted from asset) + P&L (Dr)
A10: 6 | B10: Gross Profit = (Sales + Closing Stock) − (Opening Stock + Purchases + Direct Expenses) | C10: Trading Account — Gross Profit c/d / Gross Loss c/d (IF pair)
A11: 7 | B11: Net Profit = (Gross Profit + Indirect Incomes) − Indirect Expenses | C11: P&L A/c — Net Profit / Net Loss (IF pair)
A12: 8 | B12: Closing Capital = Opening Capital + Net Profit − Net Loss − Drawings | C12: Balance Sheet — Capital (closing balance) row
A13: 9 | B13: Balance Sheet identity: Total Assets = Total Capital & Liabilities | C13: Balance Sheet — TOTAL rows + balance check
A14: 10 | B14: Why it must balance: every adjustment is posted on BOTH the Trading/P&L (expense/income effect) AND the Balance Sheet (asset/liability effect). If you post only one side, the Balance Sheet will not tally. | C14: All adjustment rows — see Adjustments sheet
A16: Assumptions (clearly flagged — NOT from user data)
A17: A1 | B17: Closing Stock value Rs 40000 is a period-end assumption (not derived from the Journal).
A18: A2 | B18: Depreciation @ 10% on Furniture & Fixtures is a policy assumption.
A19: A3 | B19: Adjustment "Salary outstanding at year end" (Rs 2000) is a period-end assumption.
A20: A4 | B20: Adjustment "Insurance prepaid at year end" (Rs 500) is a period-end assumption.
